<?xml version="1.0" ?>
<!-- =================================================================================== -->
<!-- |    This document was autogenerated by xacro from phantomx.xacro                 | -->
<!-- |    EDITING THIS FILE BY HAND IS NOT RECOMMENDED                                 | -->
<!-- =================================================================================== -->
<robot name="PhantomX" xmlns:xacro="http://www.ros.org/wiki/xacro">
  <link name="base_link"/>
  <joint name="j_phantomx_attachment" type="fixed">
    <parent link="base_link"/>
    <child link="MP_BODY"/>
    <origin rpy="0 0 0" xyz="0 0 0"/>
  </joint>
  <gazebo reference="j_phantomx_attachment">
    <implicitSpringDamper>1</implicitSpringDamper>
  </gazebo>
  <link name="MP_BODY">
    <inertial>
      <origin xyz="0 0 0"/>
      <mass value="1.97559947"/>
      <inertia ixx="3.1081800" ixy="-0.25460189" ixz="2.0318174" iyy="6.3787776" iyz="0.16417863" izz="5.3316425"/>
    </inertial>
    <visual>
      <!--origin xyz="-0.0235 0 -0.03525" rpy="0 0 0" /-->
      <origin rpy="0 0 0" xyz="0 0 0"/>
      <geometry>
        <!--box size="0.102 0.109 0.106" /-->
        <mesh filename="package://mara_description/meshes/body.STL" scale="1 1 1.1"/>
      </geometry>
      <material name="Grey">
        <color rgba="0.20 0.20 0.20 1.0"/>
      </material>
    </visual>
    <collision>
      <origin rpy="0 0 0" xyz="0 0 0"/>
      <geometry>
        <mesh filename="package://mara_description/meshes/body_coll.STL" scale="1 1 1.1"/>
      </geometry>
       <!--surface>
        <friction>
          <ode>
            <mu>50</mu>
            <mu2>50</mu2>
          </ode>
        </friction>
      </surface-->
    </collision>
  </link>
  <gazebo reference="MP_BODY">
    <material>Gazebo/Orange</material>
    <dampingFactor>0.001</dampingFactor>
    <selfCollide>1</selfCollide>
  </gazebo>
  <link name="c1_rf">
    <inertial>
      <origin rpy="0 0 0" xyz="0 -0.02633 0"/>
      <mass value="0.324357719"/>
      <inertia ixx="0.0051411124" ixy="-0.00057530255" ixz="-0.000024729049" iyy="0.0081915737" iyz="-0.000019223094" izz="0.0011379812"/>
    </inertial>
    <visual>
      <origin rpy="0 0 0" xyz="0 -0.02633 0"/>
      <geometry>
        <!--box size="0.045 0.022 0.0325" /-->
        <mesh filename="package://mara_description/meshes/connect.STL" scale="1 1 1"/>
      </geometry>
      <material name="Grey">
        <color rgba="0.20 0.20 0.20 1.0"/>
      </material>
    </visual>
    <collision>
      <origin rpy="0 0 0" xyz="0 -0.02633 0"/>
      <geometry>
        <mesh filename="package://mara_description/meshes/connect_coll.STL" scale="1 1 1"/>
      </geometry>
    </collision>
  </link>
  <link name="c2_rf">
    <inertial>
      <origin rpy="0 0 0" xyz="0 -0.02633 0"/>
      <mass value="0.324357719"/>
      <inertia ixx="0.0051411124" ixy="-0.00057530255" ixz="-0.000024729049" iyy="0.0081915737" iyz="-0.000019223094" izz="0.0011379812"/>
    </inertial>
    <visual>
      <origin rpy="0 0 0" xyz="0 -0.02633 0"/>
      <geometry>
        <!--box size="0.045 0.022 0.0325" /-->
        <mesh filename="package://mara_description/meshes/connect.STL" scale="1 1 1"/>
      </geometry>
      <material name="Grey">
        <color rgba="0.20 0.20 0.20 1.0"/>
      </material>
    </visual>
    <collision>
      <origin rpy="0 0 0" xyz="0 -0.02633 0"/>
      <geometry>
        <mesh filename="package://mara_description/meshes/connect_coll.STL" scale="1 1 1"/>
      </geometry>
    </collision>
  </link>
  <link name="thigh_rf">
    <inertial>
      <origin rpy="0 0 0" xyz="0 0 0"/>
      <mass value="0.324357719"/>
      <inertia ixx="0.0051411124" ixy="-0.00057530255" ixz="-0.000024729049" iyy="0.0081915737" iyz="-0.000019223094" izz="0.0011379812"/>
    </inertial>
    <visual>
      <origin rpy="0 0 0" xyz="0 0 0"/>
      <geometry>
        <!--box size="0.045 0.022 0.0325" /-->
        <mesh filename="package://mara_description/meshes/thigh_l.STL" scale="1 1 1"/>
      </geometry>
      <material name="Grey">
        <color rgba="0.20 0.20 0.20 1.0"/>
      </material>
    </visual>
    <collision>
      <origin rpy="0 0 0" xyz="0 0 0"/>
      <geometry>
        <mesh filename="package://mara_description/meshes/thigh_l_coll.STL" scale="1 1 1"/>
      </geometry>
    </collision>
  </link>
  <link name="tibia_rf">
    <inertial>
      <origin rpy="-5 0 0" xyz="0 0 0"/>
      <mass value="0.324357719"/>
      <inertia ixx="0.0051411124" ixy="-0.00057530255" ixz="-0.000024729049" iyy="0.0081915737" iyz="-0.000019223094" izz="0.0011379812"/>
    </inertial>
    <visual>
      <origin rpy="-5 0 0" xyz="0 0 0"/>
      <geometry>
        <mesh filename="package://mara_description/meshes/tibia_l.STL" scale="1 1 1"/>
      </geometry>
      <material name="Grey">
        <color rgba="0.20 0.20 0.20 1.0"/>
      </material>
    </visual>
    <collision>
      <origin rpy="-5 0 0" xyz="0 0 0"/>
      <geometry>
        <mesh filename="package://mara_description/meshes/tibia_l_coll_rump.STL" scale="1 1 1"/>
      </geometry>
    </collision>
    <collision>
      <origin rpy="-5 0 0" xyz="0 0 0"/>
      <geometry>
        <mesh filename="package://mara_description/meshes/tibia_l_coll_tip.STL" scale="1 1 1"/>
      </geometry>
    </collision>
  </link>
  <joint name="j_c1_rf" type="revolute">
    <parent link="MP_BODY"/>
    <child link="c1_rf"/>
    <origin rpy="0 4.7123 0.7853981633974483" xyz="0.1248 -0.06164  0.001116"/>
    <axis xyz="1 0 0"/>
    <limit effort="2.8" lower="-0.523599" upper="0.523599" velocity="5.6548668"/>
  </joint>
  <joint name="j_c2_rf" type="fixed">
    <parent link="c1_rf"/>
    <child link="c2_rf"/>
    <origin rpy="0 1.5704 3.14159" xyz="0 -0.054 0"/>
  </joint>
  <joint name="j_thigh_rf" type="revolute">
    <parent link="c2_rf"/>
    <child link="thigh_rf"/>
    <origin rpy=" 0 3.14159 3.14159" xyz="0 0 0"/>
    <axis xyz="1 0 0"/>
    <limit effort="2.8" lower="-1.5708" upper="1.5708" velocity="5.6548668"/>
  </joint>
  <joint name="j_tibia_rf" type="revolute">
    <parent link="thigh_rf"/>
    <child link="tibia_rf"/>
    <origin rpy="-1.5707 0 3.14159" xyz="0 -0.0645 -0.0145"/>
    <axis xyz="1 0 0"/>
    <limit effort="2.8" lower="-2.53073" upper="0.6179939" velocity="5.6548668"/>
  </joint>
  <transmission name="t_c1_rf">
    <type>transmission_interface/SimpleTransmission</type>
    <joint name="j_c1_rf">
      <hardwareInterface>hardware_interface/EffortJointInterface</hardwareInterface>
    </joint>
    <actuator name="m_c1_rf">
      <mechanicalReduction>1</mechanicalReduction>
    </actuator>
  </transmission>
  <transmission name="t_thigh_rf">
    <type>transmission_interface/SimpleTransmission</type>
    <joint name="j_thigh_rf">
      <hardwareInterface>hardware_interface/EffortJointInterface</hardwareInterface>
    </joint>
    <actuator name="m_thigh_rf">
      <mechanicalReduction>1</mechanicalReduction>
    </actuator>
  </transmission>
  <transmission name="t_tibia_rf">
    <type>transmission_interface/SimpleTransmission</type>
    <joint name="j_tibia_rf">
      <hardwareInterface>hardware_interface/EffortJointInterface</hardwareInterface>
    </joint>
    <actuator name="m_tibia_rf">
      <mechanicalReduction>1</mechanicalReduction>
    </actuator>
  </transmission>
  <gazebo reference="c1_rf">
    <material>Gazebo/Grey</material>
    <dampingFactor>.001</dampingFactor>
  </gazebo>
  <gazebo reference="c2_rf">
    <material>Gazebo/Orange</material>
    <dampingFactor>.01</dampingFactor>
  </gazebo>
  <gazebo reference="thigh_rf">
    <material>Gazebo/Grey</material>
    <dampingFactor>.01</dampingFactor>
  </gazebo>
  <gazebo reference="tibia_rf">
    <material>Gazebo/DarkGrey</material>
    <dampingFactor>.01</dampingFactor>
    <selfCollide>1</selfCollide>
  </gazebo>
  <gazebo reference="j_c1_rf">
    <implicitSpringDamper>1</implicitSpringDamper>
  </gazebo>
  <gazebo reference="j_c2_rf">
    <implicitSpringDamper>1</implicitSpringDamper>
  </gazebo>
  <gazebo reference="j_thigh_rf">
    <implicitSpringDamper>1</implicitSpringDamper>
  </gazebo>
  <gazebo reference="j_tibia_rf">
    <implicitSpringDamper>1</implicitSpringDamper>
  </gazebo>
  <link name="c1_rm">
    <inertial>
      <origin rpy="0 0 0" xyz="0 -0.02633 0"/>
      <mass value="0.324357719"/>
      <inertia ixx="0.0051411124" ixy="-0.00057530255" ixz="-0.000024729049" iyy="0.0081915737" iyz="-0.000019223094" izz="0.0011379812"/>
    </inertial>
    <visual>
      <origin rpy="0 0 0" xyz="0 -0.02633 0"/>
      <geometry>
        <!--box size="0.045 0.022 0.0325" /-->
        <mesh filename="package://mara_description/meshes/connect.STL" scale="1 1 1"/>
      </geometry>
      <material name="Grey">
        <color rgba="0.20 0.20 0.20 1.0"/>
      </material>
    </visual>
    <collision>
      <origin rpy="0 0 0" xyz="0 -0.02633 0"/>
      <geometry>
        <mesh filename="package://mara_description/meshes/connect_coll.STL" scale="1 1 1"/>
      </geometry>
    </collision>
  </link>
  <link name="c2_rm">
    <inertial>
      <origin rpy="0 0 0" xyz="0 -0.02633 0"/>
      <mass value="0.324357719"/>
      <inertia ixx="0.0051411124" ixy="-0.00057530255" ixz="-0.000024729049" iyy="0.0081915737" iyz="-0.000019223094" izz="0.0011379812"/>
    </inertial>
    <visual>
      <origin rpy="0 0 0" xyz="0 -0.02633 0"/>
      <geometry>
        <!--box size="0.045 0.022 0.0325" /-->
        <mesh filename="package://mara_description/meshes/connect.STL" scale="1 1 1"/>
      </geometry>
      <material name="Grey">
        <color rgba="0.20 0.20 0.20 1.0"/>
      </material>
    </visual>
    <collision>
      <origin rpy="0 0 0" xyz="0 -0.02633 0"/>
      <geometry>
        <mesh filename="package://mara_description/meshes/connect_coll.STL" scale="1 1 1"/>
      </geometry>
    </collision>
  </link>
  <link name="thigh_rm">
    <inertial>
      <origin rpy="0 0 0" xyz="0 0 0"/>
      <mass value="0.324357719"/>
      <inertia ixx="0.0051411124" ixy="-0.00057530255" ixz="-0.000024729049" iyy="0.0081915737" iyz="-0.000019223094" izz="0.0011379812"/>
    </inertial>
    <visual>
      <origin rpy="0 0 0" xyz="0 0 0"/>
      <geometry>
        <!--box size="0.045 0.022 0.0325" /-->
        <mesh filename="package://mara_description/meshes/thigh_l.STL" scale="1 1 1"/>
      </geometry>
      <material name="Grey">
        <color rgba="0.20 0.20 0.20 1.0"/>
      </material>
    </visual>
    <collision>
      <origin rpy="0 0 0" xyz="0 0 0"/>
      <geometry>
        <mesh filename="package://mara_description/meshes/thigh_l_coll.STL" scale="1 1 1"/>
      </geometry>
    </collision>
  </link>
  <link name="tibia_rm">
    <inertial>
      <origin rpy="-5 0 0" xyz="0 0 0"/>
      <mass value="0.324357719"/>
      <inertia ixx="0.0051411124" ixy="-0.00057530255" ixz="-0.000024729049" iyy="0.0081915737" iyz="-0.000019223094" izz="0.0011379812"/>
    </inertial>
    <visual>
      <origin rpy="-5 0 0" xyz="0 0 0"/>
      <geometry>
        <mesh filename="package://mara_description/meshes/tibia_l.STL" scale="1 1 1"/>
      </geometry>
      <material name="Grey">
        <color rgba="0.20 0.20 0.20 1.0"/>
      </material>
    </visual>
    <collision>
      <origin rpy="-5 0 0" xyz="0 0 0"/>
      <geometry>
        <mesh filename="package://mara_description/meshes/tibia_l_coll_rump.STL" scale="1 1 1"/>
      </geometry>
    </collision>
    <collision>
      <origin rpy="-5 0 0" xyz="0 0 0"/>
      <geometry>
        <mesh filename="package://mara_description/meshes/tibia_l_coll_tip.STL" scale="1 1 1"/>
      </geometry>
    </collision>
  </link>
  <joint name="j_c1_rm" type="revolute">
    <parent link="MP_BODY"/>
    <child link="c1_rm"/>
    <origin rpy="0 4.7123 0" xyz="0 -0.1034  0.001116"/>
    <axis xyz="1 0 0"/>
    <limit effort="2.8" lower="-0.523599" upper="0.523599" velocity="5.6548668"/>
  </joint>
  <joint name="j_c2_rm" type="fixed">
    <parent link="c1_rm"/>
    <child link="c2_rm"/>
    <origin rpy="0 1.5704 3.14159" xyz="0 -0.054 0"/>
  </joint>
  <joint name="j_thigh_rm" type="revolute">
    <parent link="c2_rm"/>
    <child link="thigh_rm"/>
    <origin rpy=" 0 3.14159 3.14159" xyz="0 0 0"/>
    <axis xyz="1 0 0"/>
    <limit effort="2.8" lower="-1.5708" upper="1.5708" velocity="5.6548668"/>
  </joint>
  <joint name="j_tibia_rm" type="revolute">
    <parent link="thigh_rm"/>
    <child link="tibia_rm"/>
    <origin rpy="-1.5707 0 3.14159" xyz="0 -0.0645 -0.0145"/>
    <axis xyz="1 0 0"/>
    <limit effort="2.8" lower="-2.53073" upper="0.6179939" velocity="5.6548668"/>
  </joint>
  <transmission name="t_c1_rm">
    <type>transmission_interface/SimpleTransmission</type>
    <joint name="j_c1_rm">
      <hardwareInterface>hardware_interface/EffortJointInterface</hardwareInterface>
    </joint>
    <actuator name="m_c1_rm">
      <mechanicalReduction>1</mechanicalReduction>
    </actuator>
  </transmission>
  <transmission name="t_thigh_rm">
    <type>transmission_interface/SimpleTransmission</type>
    <joint name="j_thigh_rm">
      <hardwareInterface>hardware_interface/EffortJointInterface</hardwareInterface>
    </joint>
    <actuator name="m_thigh_rm">
      <mechanicalReduction>1</mechanicalReduction>
    </actuator>
  </transmission>
  <transmission name="t_tibia_rm">
    <type>transmission_interface/SimpleTransmission</type>
    <joint name="j_tibia_rm">
      <hardwareInterface>hardware_interface/EffortJointInterface</hardwareInterface>
    </joint>
    <actuator name="m_tibia_rm">
      <mechanicalReduction>1</mechanicalReduction>
    </actuator>
  </transmission>
  <gazebo reference="c1_rm">
    <material>Gazebo/Grey</material>
    <dampingFactor>.001</dampingFactor>
  </gazebo>
  <gazebo reference="c2_rm">
    <material>Gazebo/Orange</material>
    <dampingFactor>.01</dampingFactor>
  </gazebo>
  <gazebo reference="thigh_rm">
    <material>Gazebo/Grey</material>
    <dampingFactor>.01</dampingFactor>
  </gazebo>
  <gazebo reference="tibia_rm">
    <material>Gazebo/Orange</material>
    <dampingFactor>.01</dampingFactor>
    <selfCollide>1</selfCollide>
  </gazebo>
  <gazebo reference="j_c1_rm">
    <implicitSpringDamper>1</implicitSpringDamper>
  </gazebo>
  <gazebo reference="j_c2_rm">
    <implicitSpringDamper>1</implicitSpringDamper>
  </gazebo>
  <gazebo reference="j_thigh_rm">
    <implicitSpringDamper>1</implicitSpringDamper>
  </gazebo>
  <gazebo reference="j_tibia_rm">
    <implicitSpringDamper>1</implicitSpringDamper>
  </gazebo>
  <link name="c1_rr">
    <inertial>
      <origin rpy="0 0 0" xyz="0 -0.02633 0"/>
      <mass value="0.324357719"/>
      <inertia ixx="0.0051411124" ixy="-0.00057530255" ixz="-0.000024729049" iyy="0.0081915737" iyz="-0.000019223094" izz="0.0011379812"/>
    </inertial>
    <visual>
      <origin rpy="0 0 0" xyz="0 -0.02633 0"/>
      <geometry>
        <!--box size="0.045 0.022 0.0325" /-->
        <mesh filename="package://mara_description/meshes/connect.STL" scale="1 1 1"/>
      </geometry>
      <material name="Grey">
        <color rgba="0.20 0.20 0.20 1.0"/>
      </material>
    </visual>
    <collision>
      <origin rpy="0 0 0" xyz="0 -0.02633 0"/>
      <geometry>
        <mesh filename="package://mara_description/meshes/connect_coll.STL" scale="1 1 1"/>
      </geometry>
    </collision>
  </link>
  <link name="c2_rr">
    <inertial>
      <origin rpy="0 0 0" xyz="0 -0.02633 0"/>
      <mass value="0.324357719"/>
      <inertia ixx="0.0051411124" ixy="-0.00057530255" ixz="-0.000024729049" iyy="0.0081915737" iyz="-0.000019223094" izz="0.0011379812"/>
    </inertial>
    <visual>
      <origin rpy="0 0 0" xyz="0 -0.02633 0"/>
      <geometry>
        <!--box size="0.045 0.022 0.0325" /-->
        <mesh filename="package://mara_description/meshes/connect.STL" scale="1 1 1"/>
      </geometry>
      <material name="Grey">
        <color rgba="0.20 0.20 0.20 1.0"/>
      </material>
    </visual>
    <collision>
      <origin rpy="0 0 0" xyz="0 -0.02633 0"/>
      <geometry>
        <mesh filename="package://mara_description/meshes/connect_coll.STL" scale="1 1 1"/>
      </geometry>
    </collision>
  </link>
  <link name="thigh_rr">
    <inertial>
      <origin rpy="0 0 0" xyz="0 0 0"/>
      <mass value="0.324357719"/>
      <inertia ixx="0.0051411124" ixy="-0.00057530255" ixz="-0.000024729049" iyy="0.0081915737" iyz="-0.000019223094" izz="0.0011379812"/>
    </inertial>
    <visual>
      <origin rpy="0 0 0" xyz="0 0 0"/>
      <geometry>
        <!--box size="0.045 0.022 0.0325" /-->
        <mesh filename="package://mara_description/meshes/thigh_l.STL" scale="1 1 1"/>
      </geometry>
      <material name="Grey">
        <color rgba="0.20 0.20 0.20 1.0"/>
      </material>
    </visual>
    <collision>
      <origin rpy="0 0 0" xyz="0 0 0"/>
      <geometry>
        <mesh filename="package://mara_description/meshes/thigh_l_coll.STL" scale="1 1 1"/>
      </geometry>
    </collision>
  </link>
  <link name="tibia_rr">
    <inertial>
      <origin rpy="-5 0 0" xyz="0 0 0"/>
      <mass value="0.324357719"/>
      <inertia ixx="0.0051411124" ixy="-0.00057530255" ixz="-0.000024729049" iyy="0.0081915737" iyz="-0.000019223094" izz="0.0011379812"/>
    </inertial>
    <visual>
      <origin rpy="-5 0 0" xyz="0 0 0"/>
      <geometry>
        <mesh filename="package://mara_description/meshes/tibia_l.STL" scale="1 1 1"/>
      </geometry>
      <material name="Grey">
        <color rgba="0.20 0.20 0.20 1.0"/>
      </material>
    </visual>
    <collision>
      <origin rpy="-5 0 0" xyz="0 0 0"/>
      <geometry>
        <mesh filename="package://mara_description/meshes/tibia_l_coll_rump.STL" scale="1 1 1"/>
      </geometry>
    </collision>
    <collision>
      <origin rpy="-5 0 0" xyz="0 0 0"/>
      <geometry>
        <mesh filename="package://mara_description/meshes/tibia_l_coll_tip.STL" scale="1 1 1"/>
      </geometry>
    </collision>
  </link>
  <joint name="j_c1_rr" type="revolute">
    <parent link="MP_BODY"/>
    <child link="c1_rr"/>
    <origin rpy="0 4.7123 -0.7853981633974483" xyz="-0.1248 -0.06164  0.001116"/>
    <axis xyz="1 0 0"/>
    <limit effort="2.8" lower="-0.523599" upper="0.523599" velocity="5.6548668"/>
  </joint>
  <joint name="j_c2_rr" type="fixed">
    <parent link="c1_rr"/>
    <child link="c2_rr"/>
    <origin rpy="0 1.5704 3.14159" xyz="0 -0.054 0"/>
  </joint>
  <joint name="j_thigh_rr" type="revolute">
    <parent link="c2_rr"/>
    <child link="thigh_rr"/>
    <origin rpy=" 0 3.14159 3.14159" xyz="0 0 0"/>
    <axis xyz="1 0 0"/>
    <limit effort="2.8" lower="-1.5708" upper="1.5708" velocity="5.6548668"/>
  </joint>
  <joint name="j_tibia_rr" type="revolute">
    <parent link="thigh_rr"/>
    <child link="tibia_rr"/>
    <origin rpy="-1.5707 0 3.14159" xyz="0 -0.0645 -0.0145"/>
    <axis xyz="1 0 0"/>
    <limit effort="2.8" lower="-2.53073" upper="0.6179939" velocity="5.6548668"/>
  </joint>
  <transmission name="t_c1_rr">
    <type>transmission_interface/SimpleTransmission</type>
    <joint name="j_c1_rr">
      <hardwareInterface>hardware_interface/EffortJointInterface</hardwareInterface>
    </joint>
    <actuator name="m_c1_rr">
      <mechanicalReduction>1</mechanicalReduction>
    </actuator>
  </transmission>
  <transmission name="t_thigh_rr">
    <type>transmission_interface/SimpleTransmission</type>
    <joint name="j_thigh_rr">
      <hardwareInterface>hardware_interface/EffortJointInterface</hardwareInterface>
    </joint>
    <actuator name="m_thigh_rr">
      <mechanicalReduction>1</mechanicalReduction>
    </actuator>
  </transmission>
  <transmission name="t_tibia_rr">
    <type>transmission_interface/SimpleTransmission</type>
    <joint name="j_tibia_rr">
      <hardwareInterface>hardware_interface/EffortJointInterface</hardwareInterface>
    </joint>
    <actuator name="m_tibia_rr">
      <mechanicalReduction>1</mechanicalReduction>
    </actuator>
  </transmission>
  <gazebo reference="c1_rr">
    <material>Gazebo/Grey</material>
    <dampingFactor>.001</dampingFactor>
  </gazebo>
  <gazebo reference="c2_rr">
    <material>Gazebo/Orange</material>
    <dampingFactor>.01</dampingFactor>
  </gazebo>
  <gazebo reference="thigh_rr">
    <material>Gazebo/Grey</material>
    <dampingFactor>.01</dampingFactor>
  </gazebo>
  <gazebo reference="tibia_rr">
    <material>Gazebo/Orange</material>
    <dampingFactor>.01</dampingFactor>
    <selfCollide>1</selfCollide>
  </gazebo>
  <gazebo reference="j_c1_rr">
    <implicitSpringDamper>1</implicitSpringDamper>
  </gazebo>
  <gazebo reference="j_c2_rr">
    <implicitSpringDamper>1</implicitSpringDamper>
  </gazebo>
  <gazebo reference="j_thigh_rr">
    <implicitSpringDamper>1</implicitSpringDamper>
  </gazebo>
  <gazebo reference="j_tibia_rr">
    <implicitSpringDamper>1</implicitSpringDamper>
  </gazebo>
  <link name="c1_lf">
    <inertial>
      <origin rpy="0 0 0" xyz="0 -0.02633 0"/>
      <mass value="0.324357719"/>
      <inertia ixx="0.0051411124" ixy="-0.00057530255" ixz="-0.000024729049" iyy="0.0081915737" iyz="-0.000019223094" izz="0.0011379812"/>
    </inertial>
    <visual>
      <origin rpy="0 0 0" xyz="0 -0.02633 0"/>
      <geometry>
        <!--box size="0.045 0.022 0.0325" /-->
        <mesh filename="package://mara_description/meshes/connect.STL" scale="1 1 1"/>
      </geometry>
      <material name="Grey">
        <color rgba="0.20 0.20 0.20 1.0"/>
      </material>
    </visual>
    <collision>
      <origin rpy="0 0 0" xyz="0 -0.02633 0"/>
      <geometry>
        <mesh filename="package://mara_description/meshes/connect_coll.STL" scale="1 1 1"/>
      </geometry>
    </collision>
  </link>
  <link name="c2_lf">
    <inertial>
      <origin rpy="0 0 0" xyz="0 -0.02633 0"/>
      <mass value="0.324357719"/>
      <inertia ixx="0.0051411124" ixy="-0.00057530255" ixz="-0.000024729049" iyy="0.0081915737" iyz="-0.000019223094" izz="0.0011379812"/>
    </inertial>
    <visual>
      <origin rpy="0 0 0" xyz="0 -0.02633 0"/>
      <geometry>
        <!--box size="0.045 0.022 0.0325" /-->
        <mesh filename="package://mara_description/meshes/connect.STL" scale="1 1 1"/>
      </geometry>
      <material name="Grey">
        <color rgba="0.20 0.20 0.20 1.0"/>
      </material>
    </visual>
    <collision>
      <origin rpy="0 0 0" xyz="0 -0.02633 0"/>
      <geometry>
        <mesh filename="package://mara_description/meshes/connect_coll.STL" scale="1 1 1"/>
      </geometry>
    </collision>
  </link>
  <link name="thigh_lf">
    <inertial>
      <origin rpy="0 0 0" xyz="0 0 0"/>
      <mass value="0.324357719"/>
      <inertia ixx="0.0051411124" ixy="-0.00057530255" ixz="-0.000024729049" iyy="0.0081915737" iyz="-0.000019223094" izz="0.0011379812"/>
    </inertial>
    <visual>
      <origin rpy="0 0 0" xyz="0 0 0"/>
      <geometry>
        <!--box size="0.045 0.022 0.0325" /-->
        <mesh filename="package://mara_description/meshes/thigh_l.STL" scale="1 1 1"/>
      </geometry>
      <material name="Grey">
        <color rgba="0.20 0.20 0.20 1.0"/>
      </material>
    </visual>
    <collision>
      <origin rpy="0 0 0" xyz="0 0 0"/>
      <geometry>
        <mesh filename="package://mara_description/meshes/thigh_l_coll.STL" scale="1 1 1"/>
      </geometry>
    </collision>
  </link>
  <link name="tibia_lf">
    <inertial>
      <origin rpy="-5 0 0" xyz="0 0 0"/>
      <mass value="0.324357719"/>
      <inertia ixx="0.0051411124" ixy="-0.00057530255" ixz="-0.000024729049" iyy="0.0081915737" iyz="-0.000019223094" izz="0.0011379812"/>
    </inertial>
    <visual>
      <origin rpy="-5 0 0" xyz="0 0 0"/>
      <geometry>
        <mesh filename="package://mara_description/meshes/tibia_l.STL" scale="1 1 1"/>
      </geometry>
      <material name="Grey">
        <color rgba="0.20 0.20 0.20 1.0"/>
      </material>
    </visual>
    <collision>
      <origin rpy="-5 0 0" xyz="0 0 0"/>
      <geometry>
        <mesh filename="package://mara_description/meshes/tibia_l_coll_rump.STL" scale="1 1 1"/>
      </geometry>
    </collision>
    <collision>
      <origin rpy="-5 0 0" xyz="0 0 0"/>
      <geometry>
        <mesh filename="package://mara_description/meshes/tibia_l_coll_tip.STL" scale="1 1 1"/>
      </geometry>
    </collision>
  </link>
  <joint name="j_c1_lf" type="revolute">
    <parent link="MP_BODY"/>
    <child link="c1_lf"/>
    <origin rpy="0 4.7123 2.356194490192345" xyz="0.1248 0.06164  0.001116"/>
    <axis xyz="1 0 0"/>
    <limit effort="2.8" lower="-0.523599" upper="0.523599" velocity="5.6548668"/>
  </joint>
  <joint name="j_c2_lf" type="fixed">
    <parent link="c1_lf"/>
    <child link="c2_lf"/>
    <origin rpy="0 1.5704 3.14159" xyz="0 -0.054 0"/>
  </joint>
  <joint name="j_thigh_lf" type="revolute">
    <parent link="c2_lf"/>
    <child link="thigh_lf"/>
    <origin rpy=" 0 3.14159 3.14159" xyz="0 0 0"/>
    <axis xyz="1 0 0"/>
    <limit effort="2.8" lower="-1.5708" upper="1.5708" velocity="5.6548668"/>
  </joint>
  <joint name="j_tibia_lf" type="revolute">
    <parent link="thigh_lf"/>
    <child link="tibia_lf"/>
    <origin rpy="-1.5707 0 3.14159" xyz="0 -0.0645 -0.0145"/>
    <axis xyz="1 0 0"/>
    <limit effort="2.8" lower="-2.53073" upper="0.6179939" velocity="5.6548668"/>
  </joint>
  <transmission name="t_c1_lf">
    <type>transmission_interface/SimpleTransmission</type>
    <joint name="j_c1_lf">
      <hardwareInterface>hardware_interface/EffortJointInterface</hardwareInterface>
    </joint>
    <actuator name="m_c1_lf">
      <mechanicalReduction>1</mechanicalReduction>
    </actuator>
  </transmission>
  <transmission name="t_thigh_lf">
    <type>transmission_interface/SimpleTransmission</type>
    <joint name="j_thigh_lf">
      <hardwareInterface>hardware_interface/EffortJointInterface</hardwareInterface>
    </joint>
    <actuator name="m_thigh_lf">
      <mechanicalReduction>1</mechanicalReduction>
    </actuator>
  </transmission>
  <transmission name="t_tibia_lf">
    <type>transmission_interface/SimpleTransmission</type>
    <joint name="j_tibia_lf">
      <hardwareInterface>hardware_interface/EffortJointInterface</hardwareInterface>
    </joint>
    <actuator name="m_tibia_lf">
      <mechanicalReduction>1</mechanicalReduction>
    </actuator>
  </transmission>
  <gazebo reference="c1_lf">
    <material>Gazebo/Grey</material>
    <dampingFactor>.001</dampingFactor>
  </gazebo>
  <gazebo reference="c2_lf">
    <material>Gazebo/Orange</material>
    <dampingFactor>.01</dampingFactor>
  </gazebo>
  <gazebo reference="thigh_lf">
    <material>Gazebo/Grey</material>
    <dampingFactor>.01</dampingFactor>
  </gazebo>
  <gazebo reference="tibia_lf">
    <material>Gazebo/DarkGrey</material>
    <dampingFactor>.01</dampingFactor>
    <selfCollide>1</selfCollide>
  </gazebo>
  <gazebo reference="j_c1_lf">
    <implicitSpringDamper>1</implicitSpringDamper>
  </gazebo>
  <gazebo reference="j_c2_lf">
    <implicitSpringDamper>1</implicitSpringDamper>
  </gazebo>
  <gazebo reference="j_thigh_lf">
    <implicitSpringDamper>1</implicitSpringDamper>
  </gazebo>
  <gazebo reference="j_tibia_lf">
    <implicitSpringDamper>1</implicitSpringDamper>
  </gazebo>
  <link name="c1_lm">
    <inertial>
      <origin rpy="0 0 0" xyz="0 -0.02633 0"/>
      <mass value="0.324357719"/>
      <inertia ixx="0.0051411124" ixy="-0.00057530255" ixz="-0.000024729049" iyy="0.0081915737" iyz="-0.000019223094" izz="0.0011379812"/>
    </inertial>
    <visual>
      <origin rpy="0 0 0" xyz="0 -0.02633 0"/>
      <geometry>
        <!--box size="0.045 0.022 0.0325" /-->
        <mesh filename="package://mara_description/meshes/connect.STL" scale="1 1 1"/>
      </geometry>
      <material name="Grey">
        <color rgba="0.20 0.20 0.20 1.0"/>
      </material>
    </visual>
    <collision>
      <origin rpy="0 0 0" xyz="0 -0.02633 0"/>
      <geometry>
        <mesh filename="package://mara_description/meshes/connect_coll.STL" scale="1 1 1"/>
      </geometry>
    </collision>
  </link>
  <link name="c2_lm">
    <inertial>
      <origin rpy="0 0 0" xyz="0 -0.02633 0"/>
      <mass value="0.324357719"/>
      <inertia ixx="0.0051411124" ixy="-0.00057530255" ixz="-0.000024729049" iyy="0.0081915737" iyz="-0.000019223094" izz="0.0011379812"/>
    </inertial>
    <visual>
      <origin rpy="0 0 0" xyz="0 -0.02633 0"/>
      <geometry>
        <!--box size="0.045 0.022 0.0325" /-->
        <mesh filename="package://mara_description/meshes/connect.STL" scale="1 1 1"/>
      </geometry>
      <material name="Grey">
        <color rgba="0.20 0.20 0.20 1.0"/>
      </material>
    </visual>
    <collision>
      <origin rpy="0 0 0" xyz="0 -0.02633 0"/>
      <geometry>
        <mesh filename="package://mara_description/meshes/connect_coll.STL" scale="1 1 1"/>
      </geometry>
    </collision>
  </link>
  <link name="thigh_lm">
    <inertial>
      <origin rpy="0 0 0" xyz="0 0 0"/>
      <mass value="0.324357719"/>
      <inertia ixx="0.0051411124" ixy="-0.00057530255" ixz="-0.000024729049" iyy="0.0081915737" iyz="-0.000019223094" izz="0.0011379812"/>
    </inertial>
    <visual>
      <origin rpy="0 0 0" xyz="0 0 0"/>
      <geometry>
        <!--box size="0.045 0.022 0.0325" /-->
        <mesh filename="package://mara_description/meshes/thigh_l.STL" scale="1 1 1"/>
      </geometry>
      <material name="Grey">
        <color rgba="0.20 0.20 0.20 1.0"/>
      </material>
    </visual>
    <collision>
      <origin rpy="0 0 0" xyz="0 0 0"/>
      <geometry>
        <mesh filename="package://mara_description/meshes/thigh_l_coll.STL" scale="1 1 1"/>
      </geometry>
    </collision>
  </link>
  <link name="tibia_lm">
    <inertial>
      <origin rpy="-5 0 0" xyz="0 0 0"/>
      <mass value="0.324357719"/>
      <inertia ixx="0.0051411124" ixy="-0.00057530255" ixz="-0.000024729049" iyy="0.0081915737" iyz="-0.000019223094" izz="0.0011379812"/>
    </inertial>
    <visual>
      <origin rpy="-5 0 0" xyz="0 0 0"/>
      <geometry>
        <mesh filename="package://mara_description/meshes/tibia_l.STL" scale="1 1 1"/>
      </geometry>
      <material name="Grey">
        <color rgba="0.20 0.20 0.20 1.0"/>
      </material>
    </visual>
    <collision>
      <origin rpy="-5 0 0" xyz="0 0 0"/>
      <geometry>
        <mesh filename="package://mara_description/meshes/tibia_l_coll_rump.STL" scale="1 1 1"/>
      </geometry>
    </collision>
    <collision>
      <origin rpy="-5 0 0" xyz="0 0 0"/>
      <geometry>
        <mesh filename="package://mara_description/meshes/tibia_l_coll_tip.STL" scale="1 1 1"/>
      </geometry>
    </collision>
  </link>
  <joint name="j_c1_lm" type="revolute">
    <parent link="MP_BODY"/>
    <child link="c1_lm"/>
    <origin rpy="0 4.7123 3.14159" xyz="0 0.1034  0.001116"/>
    <axis xyz="1 0 0"/>
    <limit effort="2.8" lower="-0.523599" upper="0.523599" velocity="5.6548668"/>
  </joint>
  <joint name="j_c2_lm" type="fixed">
    <parent link="c1_lm"/>
    <child link="c2_lm"/>
    <origin rpy="0 1.5704 3.14159" xyz="0 -0.054 0"/>
  </joint>
  <joint name="j_thigh_lm" type="revolute">
    <parent link="c2_lm"/>
    <child link="thigh_lm"/>
    <origin rpy=" 0 3.14159 3.14159" xyz="0 0 0"/>
    <axis xyz="1 0 0"/>
    <limit effort="2.8" lower="-1.5708" upper="1.5708" velocity="5.6548668"/>
  </joint>
  <joint name="j_tibia_lm" type="revolute">
    <parent link="thigh_lm"/>
    <child link="tibia_lm"/>
    <origin rpy="-1.5707 0 3.14159" xyz="0 -0.0645 -0.0145"/>
    <axis xyz="1 0 0"/>
    <limit effort="2.8" lower="-2.53073" upper="0.6179939" velocity="5.6548668"/>
  </joint>
  <transmission name="t_c1_lm">
    <type>transmission_interface/SimpleTransmission</type>
    <joint name="j_c1_lm">
      <hardwareInterface>hardware_interface/EffortJointInterface</hardwareInterface>
    </joint>
    <actuator name="m_c1_lm">
      <mechanicalReduction>1</mechanicalReduction>
    </actuator>
  </transmission>
  <transmission name="t_thigh_lm">
    <type>transmission_interface/SimpleTransmission</type>
    <joint name="j_thigh_lm">
      <hardwareInterface>hardware_interface/EffortJointInterface</hardwareInterface>
    </joint>
    <actuator name="m_thigh_lm">
      <mechanicalReduction>1</mechanicalReduction>
    </actuator>
  </transmission>
  <transmission name="t_tibia_lm">
    <type>transmission_interface/SimpleTransmission</type>
    <joint name="j_tibia_lm">
      <hardwareInterface>hardware_interface/EffortJointInterface</hardwareInterface>
    </joint>
    <actuator name="m_tibia_lm">
      <mechanicalReduction>1</mechanicalReduction>
    </actuator>
  </transmission>
  <gazebo reference="c1_lm">
    <material>Gazebo/Grey</material>
    <dampingFactor>.001</dampingFactor>
  </gazebo>
  <gazebo reference="c2_lm">
    <material>Gazebo/Orange</material>
    <dampingFactor>.01</dampingFactor>
  </gazebo>
  <gazebo reference="thigh_lm">
    <material>Gazebo/Grey</material>
    <dampingFactor>.01</dampingFactor>
  </gazebo>
  <gazebo reference="tibia_lm">
    <material>Gazebo/Orange</material>
    <dampingFactor>.01</dampingFactor>
    <selfCollide>1</selfCollide>
  </gazebo>
  <gazebo reference="j_c1_lm">
    <implicitSpringDamper>1</implicitSpringDamper>
  </gazebo>
  <gazebo reference="j_c2_lm">
    <implicitSpringDamper>1</implicitSpringDamper>
  </gazebo>
  <gazebo reference="j_thigh_lm">
    <implicitSpringDamper>1</implicitSpringDamper>
  </gazebo>
  <gazebo reference="j_tibia_lm">
    <implicitSpringDamper>1</implicitSpringDamper>
  </gazebo>
  <link name="c1_lr">
    <inertial>
      <origin rpy="0 0 0" xyz="0 -0.02633 0"/>
      <mass value="0.324357719"/>
      <inertia ixx="0.0051411124" ixy="-0.00057530255" ixz="-0.000024729049" iyy="0.0081915737" iyz="-0.000019223094" izz="0.0011379812"/>
    </inertial>
    <visual>
      <origin rpy="0 0 0" xyz="0 -0.02633 0"/>
      <geometry>
        <!--box size="0.045 0.022 0.0325" /-->
        <mesh filename="package://mara_description/meshes/connect.STL" scale="1 1 1"/>
      </geometry>
      <material name="Grey">
        <color rgba="0.20 0.20 0.20 1.0"/>
      </material>
    </visual>
    <collision>
      <origin rpy="0 0 0" xyz="0 -0.02633 0"/>
      <geometry>
        <mesh filename="package://mara_description/meshes/connect_coll.STL" scale="1 1 1"/>
      </geometry>
    </collision>
  </link>
  <link name="c2_lr">
    <inertial>
      <origin rpy="0 0 0" xyz="0 -0.02633 0"/>
      <mass value="0.324357719"/>
      <inertia ixx="0.0051411124" ixy="-0.00057530255" ixz="-0.000024729049" iyy="0.0081915737" iyz="-0.000019223094" izz="0.0011379812"/>
    </inertial>
    <visual>
      <origin rpy="0 0 0" xyz="0 -0.02633 0"/>
      <geometry>
        <!--box size="0.045 0.022 0.0325" /-->
        <mesh filename="package://mara_description/meshes/connect.STL" scale="1 1 1"/>
      </geometry>
      <material name="Grey">
        <color rgba="0.20 0.20 0.20 1.0"/>
      </material>
    </visual>
    <collision>
      <origin rpy="0 0 0" xyz="0 -0.02633 0"/>
      <geometry>
        <mesh filename="package://mara_description/meshes/connect_coll.STL" scale="1 1 1"/>
      </geometry>
    </collision>
  </link>
  <link name="thigh_lr">
    <inertial>
      <origin rpy="0 0 0" xyz="0 0 0"/>
      <mass value="0.324357719"/>
      <inertia ixx="0.0051411124" ixy="-0.00057530255" ixz="-0.000024729049" iyy="0.0081915737" iyz="-0.000019223094" izz="0.0011379812"/>
    </inertial>
    <visual>
      <origin rpy="0 0 0" xyz="0 0 0"/>
      <geometry>
        <!--box size="0.045 0.022 0.0325" /-->
        <mesh filename="package://mara_description/meshes/thigh_l.STL" scale="1 1 1"/>
      </geometry>
      <material name="Grey">
        <color rgba="0.20 0.20 0.20 1.0"/>
      </material>
    </visual>
    <collision>
      <origin rpy="0 0 0" xyz="0 0 0"/>
      <geometry>
        <mesh filename="package://mara_description/meshes/thigh_l_coll.STL" scale="1 1 1"/>
      </geometry>
    </collision>
  </link>
  <link name="tibia_lr">
    <inertial>
      <origin rpy="-5 0 0" xyz="0 0 0"/>
      <mass value="0.324357719"/>
      <inertia ixx="0.0051411124" ixy="-0.00057530255" ixz="-0.000024729049" iyy="0.0081915737" iyz="-0.000019223094" izz="0.0011379812"/>
    </inertial>
    <visual>
      <origin rpy="-5 0 0" xyz="0 0 0"/>
      <geometry>
        <mesh filename="package://mara_description/meshes/tibia_l.STL" scale="1 1 1"/>
      </geometry>
      <material name="Grey">
        <color rgba="0.20 0.20 0.20 1.0"/>
      </material>
    </visual>
    <collision>
      <origin rpy="-5 0 0" xyz="0 0 0"/>
      <geometry>
        <mesh filename="package://mara_description/meshes/tibia_l_coll_rump.STL" scale="1 1 1"/>
      </geometry>
    </collision>
    <collision>
      <origin rpy="-5 0 0" xyz="0 0 0"/>
      <geometry>
        <mesh filename="package://mara_description/meshes/tibia_l_coll_tip.STL" scale="1 1 1"/>
      </geometry>
    </collision>
  </link>
  <joint name="j_c1_lr" type="revolute">
    <parent link="MP_BODY"/>
    <child link="c1_lr"/>
    <origin rpy="0 4.7123 3.9269908169872414" xyz="-0.1248 0.06164  0.001116"/>
    <axis xyz="1 0 0"/>
    <limit effort="2.8" lower="-0.523599" upper="0.523599" velocity="5.6548668"/>
  </joint>
  <joint name="j_c2_lr" type="fixed">
    <parent link="c1_lr"/>
    <child link="c2_lr"/>
    <origin rpy="0 1.5704 3.14159" xyz="0 -0.054 0"/>
  </joint>
  <joint name="j_thigh_lr" type="revolute">
    <parent link="c2_lr"/>
    <child link="thigh_lr"/>
    <origin rpy=" 0 3.14159 3.14159" xyz="0 0 0"/>
    <axis xyz="1 0 0"/>
    <limit effort="2.8" lower="-1.5708" upper="1.5708" velocity="5.6548668"/>
  </joint>
  <joint name="j_tibia_lr" type="revolute">
    <parent link="thigh_lr"/>
    <child link="tibia_lr"/>
    <origin rpy="-1.5707 0 3.14159" xyz="0 -0.0645 -0.0145"/>
    <axis xyz="1 0 0"/>
    <limit effort="2.8" lower="-2.53073" upper="0.6179939" velocity="5.6548668"/>
  </joint>
  <transmission name="t_c1_lr">
    <type>transmission_interface/SimpleTransmission</type>
    <joint name="j_c1_lr">
      <hardwareInterface>hardware_interface/EffortJointInterface</hardwareInterface>
    </joint>
    <actuator name="m_c1_lr">
      <mechanicalReduction>1</mechanicalReduction>
    </actuator>
  </transmission>
  <transmission name="t_thigh_lr">
    <type>transmission_interface/SimpleTransmission</type>
    <joint name="j_thigh_lr">
      <hardwareInterface>hardware_interface/EffortJointInterface</hardwareInterface>
    </joint>
    <actuator name="m_thigh_lr">
      <mechanicalReduction>1</mechanicalReduction>
    </actuator>
  </transmission>
  <transmission name="t_tibia_lr">
    <type>transmission_interface/SimpleTransmission</type>
    <joint name="j_tibia_lr">
      <hardwareInterface>hardware_interface/EffortJointInterface</hardwareInterface>
    </joint>
    <actuator name="m_tibia_lr">
      <mechanicalReduction>1</mechanicalReduction>
    </actuator>
  </transmission>
  <gazebo reference="c1_lr">
    <material>Gazebo/Grey</material>
    <dampingFactor>.001</dampingFactor>
  </gazebo>
  <gazebo reference="c2_lr">
    <material>Gazebo/Orange</material>
    <dampingFactor>.01</dampingFactor>
  </gazebo>
  <gazebo reference="thigh_lr">
    <material>Gazebo/Grey</material>
    <dampingFactor>.01</dampingFactor>
  </gazebo>
  <gazebo reference="tibia_lr">
    <material>Gazebo/Orange</material>
    <dampingFactor>.01</dampingFactor>
    <selfCollide>1</selfCollide>
  </gazebo>
  <gazebo reference="j_c1_lr">
    <implicitSpringDamper>1</implicitSpringDamper>
  </gazebo>
  <gazebo reference="j_c2_lr">
    <implicitSpringDamper>1</implicitSpringDamper>
  </gazebo>
  <gazebo reference="j_thigh_lr">
    <implicitSpringDamper>1</implicitSpringDamper>
  </gazebo>
  <gazebo reference="j_tibia_lr">
    <implicitSpringDamper>1</implicitSpringDamper>
  </gazebo>
  <gazebo>
    <plugin filename="libgazebo_ros_joint_force_subscriber.so" name="phantomx_j_c1_rf_joint_force_subscriber">
      <joint_name>j_c1_rf</joint_name>
      <argument>gazebo_ros_joint_force_subscriber:=j_c1_rf/force</argument>
    </plugin>
  </gazebo>
  <gazebo>
    <plugin filename="libgazebo_ros_joint_force_subscriber.so" name="phantomx_j_thigh_rf_joint_force_subscriber">
      <joint_name>j_thigh_rf</joint_name>
      <argument>gazebo_ros_joint_force_subscriber:=j_thigh_rf/force</argument>
    </plugin>
  </gazebo>
  <gazebo>
    <plugin filename="libgazebo_ros_joint_force_subscriber.so" name="phantomx_j_tibia_rf_joint_force_subscriber">
      <joint_name>j_tibia_rf</joint_name>
      <argument>gazebo_ros_joint_force_subscriber:=j_tibia_rf/force</argument>
    </plugin>
  </gazebo>
  <gazebo>
    <plugin filename="libgazebo_ros_joint_force_subscriber.so" name="phantomx_j_c1_rm_joint_force_subscriber">
      <joint_name>j_c1_rm</joint_name>
      <argument>gazebo_ros_joint_force_subscriber:=j_c1_rm/force</argument>
    </plugin>
  </gazebo>
  <gazebo>
    <plugin filename="libgazebo_ros_joint_force_subscriber.so" name="phantomx_j_thigh_rm_joint_force_subscriber">
      <joint_name>j_thigh_rm</joint_name>
      <argument>gazebo_ros_joint_force_subscriber:=j_thigh_rm/force</argument>
    </plugin>
  </gazebo>
  <gazebo>
    <plugin filename="libgazebo_ros_joint_force_subscriber.so" name="phantomx_j_tibia_rm_joint_force_subscriber">
      <joint_name>j_tibia_rm</joint_name>
      <argument>gazebo_ros_joint_force_subscriber:=j_tibia_rm/force</argument>
    </plugin>
  </gazebo>
  <gazebo>
    <plugin filename="libgazebo_ros_joint_force_subscriber.so" name="phantomx_j_c1_rr_joint_force_subscriber">
      <joint_name>j_c1_rr</joint_name>
      <argument>gazebo_ros_joint_force_subscriber:=j_c1_rr/force</argument>
    </plugin>
  </gazebo>
  <gazebo>
    <plugin filename="libgazebo_ros_joint_force_subscriber.so" name="phantomx_j_thigh_rr_joint_force_subscriber">
      <joint_name>j_thigh_rr</joint_name>
      <argument>gazebo_ros_joint_force_subscriber:=j_thigh_rr/force</argument>
    </plugin>
  </gazebo>
  <gazebo>
    <plugin filename="libgazebo_ros_joint_force_subscriber.so" name="phantomx_j_tibia_rr_joint_force_subscriber">
      <joint_name>j_tibia_rr</joint_name>
      <argument>gazebo_ros_joint_force_subscriber:=j_tibia_rr/force</argument>
    </plugin>
  </gazebo>
  <gazebo>
    <plugin filename="libgazebo_ros_joint_force_subscriber.so" name="phantomx_j_c1_lf_joint_force_subscriber">
      <joint_name>j_c1_lf</joint_name>
      <argument>gazebo_ros_joint_force_subscriber:=j_c1_lf/force</argument>
    </plugin>
  </gazebo>
  <gazebo>
    <plugin filename="libgazebo_ros_joint_force_subscriber.so" name="phantomx_j_thigh_lf_joint_force_subscriber">
      <joint_name>j_thigh_lf</joint_name>
      <argument>gazebo_ros_joint_force_subscriber:=j_thigh_lf/force</argument>
    </plugin>
  </gazebo>
  <gazebo>
    <plugin filename="libgazebo_ros_joint_force_subscriber.so" name="phantomx_j_tibia_lf_joint_force_subscriber">
      <joint_name>j_tibia_lf</joint_name>
      <argument>gazebo_ros_joint_force_subscriber:=j_tibia_lf/force</argument>
    </plugin>
  </gazebo>
  <gazebo>
    <plugin filename="libgazebo_ros_joint_force_subscriber.so" name="phantomx_j_c1_lm_joint_force_subscriber">
      <joint_name>j_c1_lm</joint_name>
      <argument>gazebo_ros_joint_force_subscriber:=j_c1_lm/force</argument>
    </plugin>
  </gazebo>
  <gazebo>
    <plugin filename="libgazebo_ros_joint_force_subscriber.so" name="phantomx_j_thigh_lm_joint_force_subscriber">
      <joint_name>j_thigh_lm</joint_name>
      <argument>gazebo_ros_joint_force_subscriber:=j_thigh_lm/force</argument>
    </plugin>
  </gazebo>
  <gazebo>
    <plugin filename="libgazebo_ros_joint_force_subscriber.so" name="phantomx_j_tibia_lm_joint_force_subscriber">
      <joint_name>j_tibia_lm</joint_name>
      <argument>gazebo_ros_joint_force_subscriber:=j_tibia_lm/force</argument>
    </plugin>
  </gazebo>
  <gazebo>
    <plugin filename="libgazebo_ros_joint_force_subscriber.so" name="phantomx_j_c1_lr_joint_force_subscriber">
      <joint_name>j_c1_lr</joint_name>
      <argument>gazebo_ros_joint_force_subscriber:=j_c1_lr/force</argument>
    </plugin>
  </gazebo>
  <gazebo>
    <plugin filename="libgazebo_ros_joint_force_subscriber.so" name="phantomx_j_thigh_lr_joint_force_subscriber">
      <joint_name>j_thigh_lr</joint_name>
      <argument>gazebo_ros_joint_force_subscriber:=j_thigh_lr/force</argument>
    </plugin>
  </gazebo>
  <gazebo>
    <plugin filename="libgazebo_ros_joint_force_subscriber.so" name="phantomx_j_tibia_lr_joint_force_subscriber">
      <joint_name>j_tibia_lr</joint_name>
      <argument>gazebo_ros_joint_force_subscriber:=j_tibia_lr/force</argument>
    </plugin>
  </gazebo>
  <gazebo>
    <plugin name="p3d_base_controller" filename="libgazebo_ros_p3d.so">
      <alwaysOn>true</alwaysOn>
      <update_rate>25.0</update_rate>
      <body_name>base_link</body_name>
      <gaussian_noise>0.00</gaussian_noise>
      <frame_name>world</frame_name>
      <xyz_offsets>0 0 0</xyz_offsets>
      <rpy_offsets>0 0 0</rpy_offsets>
    </plugin>
  </gazebo>
  <gazebo>
    <plugin name="p3d_lf_c1_controller" filename="libgazebo_ros_p3d.so">
      <ros>
        <namespace>/lf_c1</namespace>
      </ros>
      <alwaysOn>true</alwaysOn>
      <update_rate>25.0</update_rate>
      <body_name>c1_lf</body_name>
      <gaussian_noise>0.00</gaussian_noise>
      <frame_name>base_link</frame_name>
      <xyz_offsets>0 0 0</xyz_offsets>
      <rpy_offsets>0 0 0</rpy_offsets>
    </plugin>
  </gazebo>
  <gazebo>
    <plugin name="p3d_lf_thigh_controller" filename="libgazebo_ros_p3d.so">
      <ros>
        <namespace>/lf_thigh</namespace>
      </ros>
      <alwaysOn>true</alwaysOn>
      <update_rate>25.0</update_rate>
      <body_name>thigh_lf</body_name>
      <gaussian_noise>0.00</gaussian_noise>
      <frame_name>base_link</frame_name>
      <xyz_offsets>0 0 0</xyz_offsets>
      <rpy_offsets>0 0 0</rpy_offsets>
    </plugin>
  </gazebo>
  <gazebo>
    <plugin name="p3d_lf_tibia_controller" filename="libgazebo_ros_p3d.so">
      <ros>
        <namespace>/lf_tibia</namespace>
      </ros>
      <alwaysOn>true</alwaysOn>
      <update_rate>25.0</update_rate>
      <body_name>tibia_lf</body_name>
      <gaussian_noise>0.00</gaussian_noise>
      <frame_name>base_link</frame_name>
      <xyz_offsets>0 0 0</xyz_offsets>
      <rpy_offsets>0 0 0</rpy_offsets>
    </plugin>
  </gazebo>
  <gazebo>
    <plugin name="p3d_lm_c1_controller" filename="libgazebo_ros_p3d.so">
      <ros>
        <namespace>/lm_c1</namespace>
      </ros>
      <alwaysOn>true</alwaysOn>
      <update_rate>25.0</update_rate>
      <body_name>c1_lm</body_name>
      <gaussian_noise>0.00</gaussian_noise>
      <frame_name>base_link</frame_name>
      <xyz_offsets>0 0 0</xyz_offsets>
      <rpy_offsets>0 0 0</rpy_offsets>
    </plugin>
  </gazebo>
  <gazebo>
    <plugin name="p3d_lm_thigh_controller" filename="libgazebo_ros_p3d.so">
      <ros>
        <namespace>/lm_thigh</namespace>
      </ros>
      <alwaysOn>true</alwaysOn>
      <update_rate>25.0</update_rate>
      <body_name>thigh_lm</body_name>
      <gaussian_noise>0.00</gaussian_noise>
      <frame_name>base_link</frame_name>
      <xyz_offsets>0 0 0</xyz_offsets>
      <rpy_offsets>0 0 0</rpy_offsets>
    </plugin>
  </gazebo>
  <gazebo>
    <plugin name="p3d_lm_tibia_controller" filename="libgazebo_ros_p3d.so">
      <ros>
        <namespace>/lm_tibia</namespace>
      </ros>
      <alwaysOn>true</alwaysOn>
      <update_rate>25.0</update_rate>
      <body_name>tibia_lm</body_name>
      <gaussian_noise>0.00</gaussian_noise>
      <frame_name>base_link</frame_name>
      <xyz_offsets>0 0 0</xyz_offsets>
      <rpy_offsets>0 0 0</rpy_offsets>
    </plugin>
  </gazebo>
  <gazebo>
    <plugin name="p3d_lr_c1_controller" filename="libgazebo_ros_p3d.so">
      <ros>
        <namespace>/lr_c1</namespace>
      </ros>
      <alwaysOn>true</alwaysOn>
      <update_rate>25.0</update_rate>
      <body_name>c1_lr</body_name>
      <gaussian_noise>0.00</gaussian_noise>
      <frame_name>base_link</frame_name>
      <xyz_offsets>0 0 0</xyz_offsets>
      <rpy_offsets>0 0 0</rpy_offsets>
    </plugin>
  </gazebo>
  <gazebo>
    <plugin name="p3d_lr_thigh_controller" filename="libgazebo_ros_p3d.so">
      <ros>
        <namespace>/lr_thigh</namespace>
      </ros>
      <alwaysOn>true</alwaysOn>
      <update_rate>25.0</update_rate>
      <body_name>thigh_lr</body_name>
      <gaussian_noise>0.00</gaussian_noise>
      <frame_name>base_link</frame_name>
      <xyz_offsets>0 0 0</xyz_offsets>
      <rpy_offsets>0 0 0</rpy_offsets>
    </plugin>
  </gazebo>
  <gazebo>
    <plugin name="p3d_lr_tibia_controller" filename="libgazebo_ros_p3d.so">
      <ros>
        <namespace>/lr_tibia</namespace>
      </ros>
      <alwaysOn>true</alwaysOn>
      <update_rate>25.0</update_rate>
      <body_name>tibia_lr</body_name>
      <gaussian_noise>0.00</gaussian_noise>
      <frame_name>base_link</frame_name>
      <xyz_offsets>0 0 0</xyz_offsets>
      <rpy_offsets>0 0 0</rpy_offsets>
    </plugin>
  </gazebo>
  <gazebo>
    <plugin name="p3d_rf_c1_controller" filename="libgazebo_ros_p3d.so">
      <ros>
        <namespace>/rf_c1</namespace>
      </ros>
      <alwaysOn>true</alwaysOn>
      <update_rate>25.0</update_rate>
      <body_name>c1_rf</body_name>
      <gaussian_noise>0.00</gaussian_noise>
      <frame_name>base_link</frame_name>
      <xyz_offsets>0 0 0</xyz_offsets>
      <rpy_offsets>0 0 0</rpy_offsets>
    </plugin>
  </gazebo>
  <gazebo>
    <plugin name="p3d_rf_thigh_controller" filename="libgazebo_ros_p3d.so">
      <ros>
        <namespace>/rf_thigh</namespace>
      </ros>
      <alwaysOn>true</alwaysOn>
      <update_rate>25.0</update_rate>
      <body_name>thigh_rf</body_name>
      <gaussian_noise>0.00</gaussian_noise>
      <frame_name>base_link</frame_name>
      <xyz_offsets>0 0 0</xyz_offsets>
      <rpy_offsets>0 0 0</rpy_offsets>
    </plugin>
  </gazebo>
  <gazebo>
    <plugin name="p3d_rf_tibia_controller" filename="libgazebo_ros_p3d.so">
      <ros>
        <namespace>/rf_tibia</namespace>
      </ros>
      <alwaysOn>true</alwaysOn>
      <update_rate>25.0</update_rate>
      <body_name>tibia_rf</body_name>
      <gaussian_noise>0.00</gaussian_noise>
      <frame_name>base_link</frame_name>
      <xyz_offsets>0 0 0</xyz_offsets>
      <rpy_offsets>0 0 0</rpy_offsets>
    </plugin>
  </gazebo>
  <gazebo>
    <plugin name="p3d_rm_c1_controller" filename="libgazebo_ros_p3d.so">
      <ros>
        <namespace>/rm_c1</namespace>
      </ros>
      <alwaysOn>true</alwaysOn>
      <update_rate>25.0</update_rate>
      <body_name>c1_rm</body_name>
      <gaussian_noise>0.00</gaussian_noise>
      <frame_name>base_link</frame_name>
      <xyz_offsets>0 0 0</xyz_offsets>
      <rpy_offsets>0 0 0</rpy_offsets>
    </plugin>
  </gazebo>
  <gazebo>
    <plugin name="p3d_rm_thigh_controller" filename="libgazebo_ros_p3d.so">
      <ros>
        <namespace>/rm_thigh</namespace>
      </ros>
      <alwaysOn>true</alwaysOn>
      <update_rate>25.0</update_rate>
      <body_name>thigh_rm</body_name>
      <gaussian_noise>0.00</gaussian_noise>
      <frame_name>base_link</frame_name>
      <xyz_offsets>0 0 0</xyz_offsets>
      <rpy_offsets>0 0 0</rpy_offsets>
    </plugin>
  </gazebo>
  <gazebo>
    <plugin name="p3d_rm_tibia_controller" filename="libgazebo_ros_p3d.so">
      <ros>
        <namespace>/rm_tibia</namespace>
      </ros>
      <alwaysOn>true</alwaysOn>
      <update_rate>25.0</update_rate>
      <body_name>tibia_rm</body_name>
      <gaussian_noise>0.00</gaussian_noise>
      <frame_name>base_link</frame_name>
      <xyz_offsets>0 0 0</xyz_offsets>
      <rpy_offsets>0 0 0</rpy_offsets>
    </plugin>
  </gazebo>
  <gazebo>
    <plugin name="p3d_rr_c1_controller" filename="libgazebo_ros_p3d.so">
      <ros>
        <namespace>/rr_c1</namespace>
      </ros>
      <alwaysOn>true</alwaysOn>
      <update_rate>25.0</update_rate>
      <body_name>c1_rr</body_name>
      <gaussian_noise>0.00</gaussian_noise>
      <frame_name>base_link</frame_name>
      <xyz_offsets>0 0 0</xyz_offsets>
      <rpy_offsets>0 0 0</rpy_offsets>
    </plugin>
  </gazebo>
  <gazebo>
    <plugin name="p3d_rr_thigh_controller" filename="libgazebo_ros_p3d.so">
      <ros>
        <namespace>/rr_thigh</namespace>
      </ros>
      <alwaysOn>true</alwaysOn>
      <update_rate>25.0</update_rate>
      <body_name>thigh_rr</body_name>
      <gaussian_noise>0.00</gaussian_noise>
      <frame_name>base_link</frame_name>
      <xyz_offsets>0 0 0</xyz_offsets>
      <rpy_offsets>0 0 0</rpy_offsets>
    </plugin>
  </gazebo>
  <gazebo>
    <plugin name="p3d_rr_tibia_controller" filename="libgazebo_ros_p3d.so">
      <ros>
        <namespace>/rr_tibia</namespace>
      </ros>
      <alwaysOn>true</alwaysOn>
      <update_rate>25.0</update_rate>
      <body_name>tibia_rr</body_name>
      <gaussian_noise>0.00</gaussian_noise>
      <frame_name>base_link</frame_name>
      <xyz_offsets>0 0 0</xyz_offsets>
      <rpy_offsets>0 0 0</rpy_offsets>
    </plugin>
  </gazebo>
  <gazebo reference="tibia_lf">
    <collision>
       <surface>
        <friction>
          <ode>
            <mu>10000</mu>
          </ode>
        </friction>
      </surface>
    </collision>
    <sensor name='tibia_lf_contact' type='contact'>
       <plugin name="tibia_lf_plugin" filename="libgazebo_ros_bumper.so">
          <argument>bumper_states:=tibia_lf_collision</argument>
          <frame_name>world</frame_name>
       </plugin>
          <contact>
            <collision>tibia_lf_collision_1</collision>
          </contact>
        <update_rate> 25 </update_rate>
    </sensor>
  </gazebo>
  <gazebo reference="tibia_lm">
    <collision>
       <surface>
        <friction>
          <ode>
            <mu>10000</mu>
          </ode>
        </friction>
      </surface>
    </collision>
    <sensor name='tibia_lm_contact' type='contact'>
       <plugin name="tibia_lm_contact_plugin" filename="libgazebo_ros_bumper.so">
          <argument>bumper_states:=tibia_lm_collision</argument>
          <frame_name>world</frame_name>
       </plugin>
          <contact>
            <collision>tibia_lm_collision_1</collision>
          </contact>
        <update_rate> 25 </update_rate>
    </sensor>
  </gazebo>
  <gazebo reference="tibia_lr">
    <collision>
       <surface>
        <friction>
          <ode>
            <mu>10000</mu>
          </ode>
        </friction>
      </surface>
    </collision>
    <sensor name='tibia_lr_contact' type='contact'>
       <plugin name="tibia_lr_contact_plugin" filename="libgazebo_ros_bumper.so">
          <argument>bumper_states:=tibia_lr_collision</argument>
          <frame_name>world</frame_name>
       </plugin>
          <contact>
            <collision>tibia_lr_collision_1</collision>
          </contact>
        <update_rate> 25 </update_rate>
    </sensor>
  </gazebo>
    <gazebo reference="tibia_rf">
    <collision>
       <surface>
        <friction>
          <ode>
            <mu>10000</mu>
          </ode>
        </friction>
      </surface>
    </collision>
    <sensor name='tibia_rf_contact' type='contact'>
       <plugin name="tibia_rf_contact_plugin" filename="libgazebo_ros_bumper.so">
          <argument>bumper_states:=tibia_rf_collision</argument>
          <frame_name>world</frame_name>
       </plugin>
          <contact>
            <collision>tibia_rf_collision_1</collision>
          </contact>
        <update_rate> 25 </update_rate>
    </sensor>
  </gazebo>
  <gazebo reference="tibia_rm">
    <collision>
       <surface>
        <friction>
          <ode>
            <mu>10000</mu>
          </ode>
        </friction>
      </surface>
    </collision>
    <sensor name='tibia_rm_contact' type='contact'>
       <plugin name="tibia_rm_contact_plugin" filename="libgazebo_ros_bumper.so">
          <argument>bumper_states:=tibia_rm_collision</argument>
          <frame_name>world</frame_name>
       </plugin>
          <contact>
            <collision>tibia_rm_collision_1</collision>
          </contact>
        <update_rate> 25 </update_rate>
    </sensor>
  </gazebo>
  <gazebo reference="tibia_rr">
    <collision>
       <surface>
        <friction>
          <ode>
            <mu>10000</mu>
          </ode>
        </friction>
      </surface>
    </collision>
    <sensor name='tibia_rr_contact' type='contact'>
       <plugin name="tibia_rr_contact_plugin" filename="libgazebo_ros_bumper.so">
          <argument>bumper_states:=tibia_rr_collision</argument>
          <frame_name>world</frame_name>
       </plugin>
          <contact>
            <collision>tibia_rr_collision_1</collision>
          </contact>
        <update_rate> 25 </update_rate>
    </sensor>
  </gazebo>
  <gazebo reference="base_link">
    <sensor name='body_contact' type='contact'>
       <plugin name="body_contact_plugin" filename="libgazebo_ros_bumper.so">
          <argument>bumper_states:=body_collision</argument>
          <frame_name>world</frame_name>
       </plugin>
          <contact>
            <collision>base_link_fixed_joint_lump__MP_BODY_collision</collision>
          </contact>
        <update_rate> 25 </update_rate>
    </sensor>
  </gazebo>

</robot>
